Workbook

Sheet TechLayoffsTracker
A1: Nr | B1: Company | C1: Location_HQ | D1: Region | E1: USState | F1: Country | G1: Continent | H1: Laid_Off | I1: Date_layoffs | J1: Percentage | K1: Company_Size_before_Layoffs | L1: Company_Size_after_layoffs | M1: Industry | N1: Stage | O1: Money_Raised_in__mil | P1: Year | Q1: latitude | R1: longitude
A2: 1 | B2: Tamara Mellon | C2: Los Angeles | D2: =VLOOKUP(C2,layoffs_location!A:B,2,FALSE) -> other | E2: =VLOOKUP(C2,layoffs_location!A:C,3,FALSE) -> California | F2: =VLOOKUP(C2,layoffs_location!A:D,4,FALSE) -> USA | G2: =VLOOKUP(C2,layoffs_location!A:E,5,FALSE) -> North America | H2: 20 | I2: 43902 | J2: 40 | K2: 50 | L2: 30 | M2: Retail | N2: Series C | O2: 90 | P2: 2020 | Q2: =VLOOKUP(C2,layoffs_location!A:F,6,FALSE) -> 34.053691 | R2: =VLOOKUP(C2,layoffs_location!A:G,7,FALSE) -> -118.24277
A3: 2 | B3: HopSkipDrive | C3: Los Angeles | D3: =VLOOKUP(C3,layoffs_location!A:B,2,FALSE) -> other | E3: =VLOOKUP(C3,layoffs_location!A:C,3,FALSE) -> California | F3: =VLOOKUP(C3,layoffs_location!A:D,4,FALSE) -> USA | G3: =VLOOKUP(C3,layoffs_location!A:E,5,FALSE) -> North America | H3: 8 | I3: 43903 | J3: 10 | K3: 80 | L3: 72 | M3: Transportation | N3: Unknown | O3: 45 | P3: 2020 | Q3: =VLOOKUP(C3,layoffs_location!A:F,6,FALSE) -> 34.053691 | R3: =VLOOKUP(C3,layoffs_location!A:G,7,FALSE) -> -118.24277
A4: 3 | B4: Panda Squad | C4: San Francisco | D4: =VLOOKUP(C4,layoffs_location!A:B,2,FALSE) -> San Francisco Bay Area | E4: =VLOOKUP(C4,layoffs_location!A:C,3,FALSE) -> California | F4: =VLOOKUP(C4,layoffs_location!A:D,4,FALSE) -> USA | G4: =VLOOKUP(C4,layoffs_location!A:E,5,FALSE) -> North America | H4: 6 | I4: 43903 | J4: 75 | K4: 8 | L4: 2 | M4: Consumer | N4: Seed | O4: 1 | P4: 2020 | Q4: =VLOOKUP(C4,layoffs_location!A:F,6,FALSE) -> 37.779259 | R4: =VLOOKUP(C4,layoffs_location!A:G,7,FALSE) -> -122.41933
A5: 4 | B5: Help.com | C5: Austin | D5: =VLOOKUP(C5,layoffs_location!A:B,2,FALSE) -> other | E5: =VLOOKUP(C5,layoffs_location!A:C,3,FALSE) -> Texas | F5: =VLOOKUP(C5,layoffs_location!A:D,4,FALSE) -> USA | G5: =VLOOKUP(C5,layoffs_location!A:E,5,FALSE) -> North America | H5: 16 | I5: 43906 | J5: 100 | K5: 16 | L5: 0 | M5: Support | N5: Seed | O5: 6 | P5: 2020 | Q5: =VLOOKUP(C5,layoffs_location!A:F,6,FALSE) -> 30.271129 | R5: =VLOOKUP(C5,layoffs_location!A:G,7,FALSE) -> -97.7437
A6: 5 | B6: Inspirato | C6: Denver | D6: =VLOOKUP(C6,layoffs_location!A:B,2,FALSE) -> other | E6: =VLOOKUP(C6,layoffs_location!A:C,3,FALSE) -> Colorado | F6: =VLOOKUP(C6,layoffs_location!A:D,4,FALSE) -> USA | G6: =VLOOKUP(C6,layoffs_location!A:E,5,FALSE) -> North America | H6: 130 | I6: 43906 | J6: 22 | K6: 591 | L6: 461 | M6: Travel | N6: Series C | O6: 79 | P6: 2020 | Q6: =VLOOKUP(C6,layoffs_location!A:F,6,FALSE) -> 39.739236 | R6: =VLOOKUP(C6,layoffs_location!A:G,7,FALSE) -> -104.98486
A7: 6 | B7: Flytedesk | C7: Boulder | D7: =VLOOKUP(C7,layoffs_location!A:B,2,FALSE) -> other | E7: =VLOOKUP(C7,layoffs_location!A:C,3,FALSE) -> Colorado | F7: =VLOOKUP(C7,layoffs_location!A:D,4,FALSE) -> USA | G7: =VLOOKUP(C7,layoffs_location!A:E,5,FALSE) -> North America | H7: 4 | I7: 43908 | J7: 20 | K7: 20 | L7: 16 | M7: Marketing | N7: Seed | O7: 4 | P7: 2020 | Q7: =VLOOKUP(C7,layoffs_location!A:F,6,FALSE) -> 40.014986 | R7: =VLOOKUP(C7,layoffs_location!A:G,7,FALSE) -> -105.27054
A8: 7 | B8: Remote Year | C8: Chicago | D8: =VLOOKUP(C8,layoffs_location!A:B,2,FALSE) -> other | E8: =VLOOKUP(C8,layoffs_location!A:C,3,FALSE) -> Illinois | F8: =VLOOKUP(C8,layoffs_location!A:D,4,FALSE) -> USA | G8: =VLOOKUP(C8,layoffs_location!A:E,5,FALSE) -> North America | H8: 50 | I8: 43909 | J8: 50 | K8: 100 | L8: 50 | M8: Travel | N8: Series B | O8: 17 | P8: 2020 | Q8: =VLOOKUP(C8,layoffs_location!A:F,6,FALSE) -> 41.875562 | R8: =VLOOKUP(C8,layoffs_location!A:G,7,FALSE) -> -87.624421
A9: 8 | B9: CTO.ai | C9: Vancouver | D9: =VLOOKUP(C9,layoffs_location!A:B,2,FALSE) -> Cascadia | E9: =VLOOKUP(C9,layoffs_location!A:C,3,FALSE) -> British Columbia | F9: =VLOOKUP(C9,layoffs_location!A:D,4,FALSE) -> Canada | G9: =VLOOKUP(C9,layoffs_location!A:E,5,FALSE) -> North America | H9: 30 | I9: 43910 | J9: 50 | K9: 60 | L9: 30 | M9: Infrastructure | N9: Seed | O9: 7 | P9: 2020 | Q9: =VLOOKUP(C9,layoffs_location!A:F,6,FALSE) -> 49.260872 | R9: =VLOOKUP(C9,layoffs_location!A:G,7,FALSE) -> -123.11395
A10: 9 | B10: Flywheel Sports | C10: New York City | D10: =VLOOKUP(C10,layoffs_location!A:B,2,FALSE) -> New York | E10: =VLOOKUP(C10,layoffs_location!A:C,3,FALSE) -> New York | F10: =VLOOKUP(C10,layoffs_location!A:D,4,FALSE) -> USA | G10: =VLOOKUP(C10,layoffs_location!A:E,5,FALSE) -> North America | H10: 784 | I10: 43910 | J10: 98 | K10: 800 | L10: 16 | M10: Fitness | N10: Acquired | O10: 120 | P10: 2020 | Q10: =VLOOKUP(C10,layoffs_location!A:F,6,FALSE) -> 40.712728 | R10: =VLOOKUP(C10,layoffs_location!A:G,7,FALSE) -> -74.006015
A11: 10 | B11: Compass | C11: New York City | D11: =VLOOKUP(C11,layoffs_location!A:B,2,FALSE) -> New York | E11: =VLOOKUP(C11,layoffs_location!A:C,3,FALSE) -> New York | F11: =VLOOKUP(C11,layoffs_location!A:D,4,FALSE) -> USA | G11: =VLOOKUP(C11,layoffs_location!A:E,5,FALSE) -> North America | H11: 375 | I11: 43913 | J11: 15 | K11: 2500 | L11: 2125 | M11: Real Estate | N11: Series G | O11: 1600 | P11: 2020 | Q11: =VLOOKUP(C11,layoffs_location!A:F,6,FALSE) -> 40.712728 | R11: =VLOOKUP(C11,layoffs_location!A:G,7,FALSE) -> -74.006015
A12: 11 | B12: Convene | C12: New York City | D12: =VLOOKUP(C12,layoffs_location!A:B,2,FALSE) -> New York | E12: =VLOOKUP(C12,layoffs_location!A:C,3,FALSE) -> New York | F12: =VLOOKUP(C12,layoffs_location!A:D,4,FALSE) -> USA | G12: =VLOOKUP(C12,layoffs_location!A:E,5,FALSE) -> North America | H12: 150 | I12: 43913 | J12: 18 | K12: 833 | L12: 683 | M12: Real Estate | N12: Series D | O12: 280 | P12: 2020 | Q12: =VLOOKUP(C12,layoffs_location!A:F,6,FALSE) -> 40.712728 | R12: =VLOOKUP(C12,layoffs_location!A:G,7,FALSE) -> -74.006015
A13: 12 | B13: GrayMeta | C13: Los Angeles | D13: =VLOOKUP(C13,layoffs_location!A:B,2,FALSE) -> other | E13: =VLOOKUP(C13,layoffs_location!A:C,3,FALSE) -> California | F13: =VLOOKUP(C13,layoffs_location!A:D,4,FALSE) -> USA | G13: =VLOOKUP(C13,layoffs_location!A:E,5,FALSE) -> North America | H13: 20 | I13: 43913 | J13: 40 | K13: 50 | L13: 30 | M13: Data | N13: Unknown | O13: 7 | P13: 2020 | Q13: =VLOOKUP(C13,layoffs_location!A:F,6,FALSE) -> 34.053691 | R13: =VLOOKUP(C13,layoffs_location!A:G,7,FALSE) -> -118.24277
... A23: 22 | B23: Overtime | C23: New York City | D23: =VLOOKUP(C23,layoffs_location!A:B,2,FALSE) -> New York | E23: =VLOOKUP(C23,layoffs_location!A:C,3,FALSE) -> New York | F23: =VLOOKUP(C23,layoffs_location!A:D,4,FALSE) -> USA | G23: =VLOOKUP(C23,layoffs_location!A:E,5,FALSE) -> North America | H23: 30 | I23: 43915 | J23: 23 | K23: 130 | L23: 100 | M23: Media | N23: Series B | O23: 35 | P23: 2020 | Q23: =VLOOKUP(C23,layoffs_location!A:F,6,FALSE) -> 40.712728 | R23: =VLOOKUP(C23,layoffs_location!A:G,7,FALSE) -> -74.006015
A24: 23 | B24: TripActions | C24: Palo Alto | D24: =VLOOKUP(C24,layoffs_location!A:B,2,FALSE) -> San Francisco Bay Area | E24: =VLOOKUP(C24,layoffs_location!A:C,3,FALSE) -> California | F24: =VLOOKUP(C24,layoffs_location!A:D,4,FALSE) -> USA | G24: =VLOOKUP(C24,layoffs_location!A:E,5,FALSE) -> North America | H24: 300 | I24: 43915 | J24: 25 | K24: 1200 | L24: 900 | M24: Travel | N24: Series D | P24: 2020 | Q24: =VLOOKUP(C24,layoffs_location!A:F,6,FALSE) -> 37.444329 | R24: =VLOOKUP(C24,layoffs_location!A:G,7,FALSE) -> -122.15985
A25: 24 | B25: WanderJaunt | C25: San Francisco | D25: =VLOOKUP(C25,layoffs_location!A:B,2,FALSE) -> San Francisco Bay Area | E25: =VLOOKUP(C25,layoffs_location!A:C,3,FALSE) -> California | F25: =VLOOKUP(C25,layoffs_location!A:D,4,FALSE) -> USA | G25: =VLOOKUP(C25,layoffs_location!A:E,5,FALSE) -> North America | H25: 56 | I25: 43915 | J25: 23 | K25: 243 | L25: 187 | M25: Travel | N25: Series B | O25: 26 | P25: 2020 | Q25: =VLOOKUP(C25,layoffs_location!A:F,6,FALSE) -> 37.779259 | R25: =VLOOKUP(C25,layoffs_location!A:G,7,FALSE) -> -122.41933
A26: 25 | B26: Wonderschool | C26: San Francisco | D26: =VLOOKUP(C26,layoffs_location!A:B,2,FALSE) -> San Francisco Bay Area | E26: =VLOOKUP(C26,layoffs_location!A:C,3,FALSE) -> California | F26: =VLOOKUP(C26,layoffs_location!A:D,4,FALSE) -> USA | G26: =VLOOKUP(C26,layoffs_location!A:E,5,FALSE) -> North America | H26: 50 | I26: 43915 | J26: 75 | K26: 67 | L26: 17 | M26: Education | N26: Series A | O26: 24 | P26: 2020 | Q26: =VLOOKUP(C26,layoffs_location!A:F,6,FALSE) -> 37.779259 | R26: =VLOOKUP(C26,layoffs_location!A:G,7,FALSE) -> -122.41933
A27: 26 | B27: B8ta | C27: San Francisco | D27: =VLOOKUP(C27,layoffs_location!A:B,2,FALSE) -> San Francisco Bay Area | E27: =VLOOKUP(C27,layoffs_location!A:C,3,FALSE) -> California | F27: =VLOOKUP(C27,layoffs_location!A:D,4,FALSE) -> USA | G27: =VLOOKUP(C27,layoffs_location!A:E,5,FALSE) -> North America | H27: 250 | I27: 43916 | J27: 50 | K27: 500 | L27: 250 | M27: Retail | N27: Series C | O27: 88 | P27: 2020 | Q27: =VLOOKUP(C27,layoffs_location!A:F,6,FALSE) -> 37.779259 | R27: =VLOOKUP(C27,layoffs_location!A:G,7,FALSE) -> -122.41933
A28: 27 | B28: Consider.co | C28: Mountain View | D28: =VLOOKUP(C28,layoffs_location!A:B,2,FALSE) -> San Francisco Bay Area | E28: =VLOOKUP(C28,layoffs_location!A:C,3,FALSE) -> California | F28: =VLOOKUP(C28,layoffs_location!A:D,4,FALSE) -> USA | G28: =VLOOKUP(C28,layoffs_location!A:E,5,FALSE) -> North America | H28: 13 | I28: 43916 | J28: 100 | K28: 13 | L28: 0 | M28: Other | N28: Seed | O28: 5 | P28: 2020 | Q28: =VLOOKUP(C28,layoffs_location!A:F,6,FALSE) -> 37.389389 | R28: =VLOOKUP(C28,layoffs_location!A:G,7,FALSE) -> -122.08321
A29: 28 | B29: Ecobee | C29: Toronto | D29: =VLOOKUP(C29,layoffs_location!A:B,2,FALSE) -> other | E29: =VLOOKUP(C29,layoffs_location!A:C,3,FALSE) -> Ontario | F29: =VLOOKUP(C29,layoffs_location!A:D,4,FALSE) -> Canada | G29: =VLOOKUP(C29,layoffs_location!A:E,5,FALSE) -> North America | H29: 47 | I29: 43916 | J29: 10 | K29: 470 | L29: 423 | M29: Energy | N29: Series C | O29: 149 | P29: 2020 | Q29: =VLOOKUP(C29,layoffs_location!A:F,6,FALSE) -> 43.653482 | R29: =VLOOKUP(C29,layoffs_location!A:G,7,FALSE) -> -79.383935
A30: 29 | B30: GoSpotCheck | C30: Denver | D30: =VLOOKUP(C30,layoffs_location!A:B,2,FALSE) -> other | E30: =VLOOKUP(C30,layoffs_location!A:C,3,FALSE) -> Colorado | F30: =VLOOKUP(C30,layoffs_location!A:D,4,FALSE) -> USA | G30: =VLOOKUP(C30,layoffs_location!A:E,5,FALSE) -> North America | H30: 23 | I30: 43916 | J30: 20 | K30: 115 | L30: 92 | M30: Retail | N30: Series B | O30: 47 | P30: 2020 | Q30: =VLOOKUP(C30,layoffs_location!A:F,6,FALSE) -> 39.739236 | R30: =VLOOKUP(C30,layoffs_location!A:G,7,FALSE) -> -104.98486
A31: 30 | B31: Peerspace | C31: San Francisco | D31: =VLOOKUP(C31,layoffs_location!A:B,2,FALSE) -> San Francisco Bay Area | E31: =VLOOKUP(C31,layoffs_location!A:C,3,FALSE) -> California | F31: =VLOOKUP(C31,layoffs_location!A:D,4,FALSE) -> USA | G31: =VLOOKUP(C31,layoffs_location!A:E,5,FALSE) -> North America | H31: 41 | I31: 43916 | J31: 75 | K31: 55 | L31: 14 | M31: Real Estate | N31: Series B | O31: 34 | P31: 2020 | Q31: =VLOOKUP(C31,layoffs_location!A:F,6,FALSE) -> 37.779259 | R31: =VLOOKUP(C31,layoffs_location!A:G,7,FALSE) -> -122.41933
A32: 31 | B32: Puppet | C32: Portland | D32: =VLOOKUP(C32,layoffs_location!A:B,2,FALSE) -> Cascadia | E32: =VLOOKUP(C32,layoffs_location!A:C,3,FALSE) -> Oregon | F32: =VLOOKUP(C32,layoffs_location!A:D,4,FALSE) -> USA | G32: =VLOOKUP(C32,layoffs_location!A:E,5,FALSE) -> North America | H32: 50 | I32: 43916 | J32: 10 | K32: 500 | L32: 450 | M32: Infrastructure | N32: Series F | O32: 149 | P32: 2020 | Q32: =VLOOKUP(C32,layoffs_location!A:F,6,FALSE) -> 45.520247 | R32: =VLOOKUP(C32,layoffs_location!A:G,7,FALSE) -> -122.67419
A33: 32 | B33: Bench | C33: Vancouver | D33: =VLOOKUP(C33,layoffs_location!A:B,2,FALSE) -> Cascadia | E33: =VLOOKUP(C33,layoffs_location!A:C,3,FALSE) -> British Columbia | F33: =VLOOKUP(C33,layoffs_location!A:D,4,FALSE) -> Canada | G33: =VLOOKUP(C33,layoffs_location!A:E,5,FALSE) -> North America | H33: 47 | I33: 43917 | J33: 10 | K33: 470 | L33: 423 | M33: Finance | N33: Series B | O33: 49 | P33: 2020 | Q33: =VLOOKUP(C33,layoffs_location!A:F,6,FALSE) -> 49.260872 | R33: =VLOOKUP(C33,layoffs_location!A:G,7,FALSE) -> -123.11395
A34: 33 | B34: Bevi | C34: Boston | D34: =VLOOKUP(C34,layoffs_location!A:B,2,FALSE) -> other | E34: =VLOOKUP(C34,layoffs_location!A:C,3,FALSE) -> Massachusetts | F34: =VLOOKUP(C34,layoffs_location!A:D,4,FALSE) -> USA | G34: =VLOOKUP(C34,layoffs_location!A:E,5,FALSE) -> North America | H34: 30 | I34: 43917 | J34: 20 | K34: 150 | L34: 120 | M34: Food | N34: Series C | O34: 60 | P34: 2020 | Q34: =VLOOKUP(C34,layoffs_location!A:F,6,FALSE) -> 42.355433 | R34: =VLOOKUP(C34,layoffs_location!A:G,7,FALSE) -> -71.060511
A35: 34 | B35: Bird | C35: Los Angeles | D35: =VLOOKUP(C35,layoffs_location!A:B,2,FALSE) -> other | E35: =VLOOKUP(C35,layoffs_location!A:C,3,FALSE) -> California | F35: =VLOOKUP(C35,layoffs_location!A:D,4,FALSE) -> USA | G35: =VLOOKUP(C35,layoffs_location!A:E,5,FALSE) -> North America | H35: 406 | I35: 43917 | J35: 30 | K35: 1353 | L35: 947 | M35: Transportation | N35: Series D | O35: 623 | P35: 2020 | Q35: =VLOOKUP(C35,layoffs_location!A:F,6,FALSE) -> 34.053691 | R35: =VLOOKUP(C35,layoffs_location!A:G,7,FALSE) -> -118.24277
A36: 35 | B36: Blueground | C36: New York City | D36: =VLOOKUP(C36,layoffs_location!A:B,2,FALSE) -> New York | E36: =VLOOKUP(C36,layoffs_location!A:C,3,FALSE) -> New York | F36: =VLOOKUP(C36,layoffs_location!A:D,4,FALSE) -> USA | G36: =VLOOKUP(C36,layoffs_location!A:E,5,FALSE) -> North America | H36: 130 | I36: 43917 | J36: 25 | K36: 520 | L36: 390 | M36: Real Estate | N36: Series B | O36: 77 | P36: 2020 | Q36: =VLOOKUP(C36,layoffs_location!A:F,6,FALSE) -> 40.712728 | R36: =VLOOKUP(C36,layoffs_location!A:G,7,FALSE) -> -74.006015
... A41: 40 | B41: Mogo | C41: Vancouver | D41: =VLOOKUP(C41,layoffs_location!A:B,2,FALSE) -> Cascadia | E41: =VLOOKUP(C41,layoffs_location!A:C,3,FALSE) -> British Columbia | F41: =VLOOKUP(C41,layoffs_location!A:D,4,FALSE) -> Canada | G41: =VLOOKUP(C41,layoffs_location!A:E,5,FALSE) -> North America | H41: 78 | I41: 43917 | J41: 30 | K41: 260 | L41: 182 | M41: Finance | N41: Post-IPO | O41: 201 | P41: 2020 | Q41: =VLOOKUP(C41,layoffs_location!A:F,6,FALSE) -> 49.260872 | R41: =VLOOKUP(C41,layoffs_location!A:G,7,FALSE) -> -123.11395
A42: 41 | B42: OneWeb | C42: London | D42: =VLOOKUP(C42,layoffs_location!A:B,2,FALSE) -> other | E42: =VLOOKUP(C42,layoffs_location!A:C,3,FALSE) -> England | F42: =VLOOKUP(C42,layoffs_location!A:D,4,FALSE) -> UK | G42: =VLOOKUP(C42,layoffs_location!A:E,5,FALSE) -> Europe | H42: 451 | I42: 43917 | J42: 85 | K42: 531 | L42: 80 | M42: Aerospace | N42: Unknown | P42: 2020 | Q42: =VLOOKUP(C42,layoffs_location!A:F,6,FALSE) -> 51.489334 | R42: =VLOOKUP(C42,layoffs_location!A:G,7,FALSE) -> -0.14405508
A43: 42 | B43: Textio | C43: Seattle | D43: =VLOOKUP(C43,layoffs_location!A:B,2,FALSE) -> Cascadia | E43: =VLOOKUP(C43,layoffs_location!A:C,3,FALSE) -> Washington | F43: =VLOOKUP(C43,layoffs_location!A:D,4,FALSE) -> USA | G43: =VLOOKUP(C43,layoffs_location!A:E,5,FALSE) -> North America | H43: 30 | I43: 43917 | J43: 20 | K43: 150 | L43: 120 | M43: HR | N43: Unknown | O43: 41 | P43: 2020 | Q43: =VLOOKUP(C43,layoffs_location!A:F,6,FALSE) -> 47.603832 | R43: =VLOOKUP(C43,layoffs_location!A:G,7,FALSE) -> -122.33006
A44: 43 | B44: Zipcar | C44: Boston | D44: =VLOOKUP(C44,layoffs_location!A:B,2,FALSE) -> other | E44: =VLOOKUP(C44,layoffs_location!A:C,3,FALSE) -> Massachusetts | F44: =VLOOKUP(C44,layoffs_location!A:D,4,FALSE) -> USA | G44: =VLOOKUP(C44,layoffs_location!A:E,5,FALSE) -> North America | H44: 100 | I44: 43917 | J44: 20 | K44: 500 | L44: 400 | M44: Transportation | N44: Acquired | O44: 107 | P44: 2020 | Q44: =VLOOKUP(C44,layoffs_location!A:F,6,FALSE) -> 42.355433 | R44: =VLOOKUP(C44,layoffs_location!A:G,7,FALSE) -> -71.060511
A45: 44 | B45: TravelTriangle | C45: Gurugram | D45: =VLOOKUP(C45,layoffs_location!A:B,2,FALSE) -> other | E45: =VLOOKUP(C45,layoffs_location!A:C,3,FALSE) -> Haryana | F45: =VLOOKUP(C45,layoffs_location!A:D,4,FALSE) -> India | G45: =VLOOKUP(C45,layoffs_location!A:E,5,FALSE) -> Asia | H45: 250 | I45: 43918 | J45: 50 | K45: 500 | L45: 250 | M45: Travel | N45: Series D | O45: 47 | P45: 2020 | Q45: =VLOOKUP(C45,layoffs_location!A:F,6,FALSE) -> 28.464615 | R45: =VLOOKUP(C45,layoffs_location!A:G,7,FALSE) -> 77.029919
A46: 45 | B46: Amplero | C46: Seattle | D46: =VLOOKUP(C46,layoffs_location!A:B,2,FALSE) -> Cascadia | E46: =VLOOKUP(C46,layoffs_location!A:C,3,FALSE) -> Washington | F46: =VLOOKUP(C46,layoffs_location!A:D,4,FALSE) -> USA | G46: =VLOOKUP(C46,layoffs_location!A:E,5,FALSE) -> North America | H46: 17 | I46: 43919 | J46: 100 | K46: 17 | L46: 0 | M46: Marketing | N46: Series B | O46: 25 | P46: 2020 | Q46: =VLOOKUP(C46,layoffs_location!A:F,6,FALSE) -> 47.603832 | R46: =VLOOKUP(C46,layoffs_location!A:G,7,FALSE) -> -122.33006
A47: 46 | B47: ZipRecruiter | C47: Los Angeles | D47: =VLOOKUP(C47,layoffs_location!A:B,2,FALSE) -> other | E47: =VLOOKUP(C47,layoffs_location!A:C,3,FALSE) -> California | F47: =VLOOKUP(C47,layoffs_location!A:D,4,FALSE) -> USA | G47: =VLOOKUP(C47,layoffs_location!A:E,5,FALSE) -> North America | H47: 400 | I47: 43919 | J47: 39 | K47: 1026 | L47: 626 | M47: HR | N47: Series B | O47: 219 | P47: 2020 | Q47: =VLOOKUP(C47,layoffs_location!A:F,6,FALSE) -> 34.053691 | R47: =VLOOKUP(C47,layoffs_location!A:G,7,FALSE) -> -118.24277
A48: 47 | B48: FabHotels | C48: New Delhi | D48: =VLOOKUP(C48,layoffs_location!A:B,2,FALSE) -> other | E48: =VLOOKUP(C48,layoffs_location!A:C,3,FALSE) -> Delhi | F48: =VLOOKUP(C48,layoffs_location!A:D,4,FALSE) -> India | G48: =VLOOKUP(C48,layoffs_location!A:E,5,FALSE) -> Asia | H48: 80 | I48: 43920 | J48: 20 | K48: 400 | L48: 320 | M48: Travel | N48: Series B | O48: 48 | P48: 2020 | Q48: =VLOOKUP(C48,layoffs_location!A:F,6,FALSE) -> 28.613895 | R48: =VLOOKUP(C48,layoffs_location!A:G,7,FALSE) -> 77.209006
A49: 48 | B49: Hibob | C49: Tel Aviv | D49: =VLOOKUP(C49,layoffs_location!A:B,2,FALSE) -> other | E49: =VLOOKUP(C49,layoffs_location!A:C,3,FALSE) -> non | F49: =VLOOKUP(C49,layoffs_location!A:D,4,FALSE) -> Israel | G49: =VLOOKUP(C49,layoffs_location!A:E,5,FALSE) -> Asia | H49: 70 | I49: 43920 | J49: 30 | K49: 233 | L49: 163 | M49: HR | N49: Series A | O49: 45 | P49: 2020 | Q49: =VLOOKUP(C49,layoffs_location!A:F,6,FALSE) -> 32.0853 | R49: =VLOOKUP(C49,layoffs_location!A:G,7,FALSE) -> 34.781806
A50: 49 | B50: Iris Nova | C50: New York City | D50: =VLOOKUP(C50,layoffs_location!A:B,2,FALSE) -> New York | E50: =VLOOKUP(C50,layoffs_location!A:C,3,FALSE) -> New York | F50: =VLOOKUP(C50,layoffs_location!A:D,4,FALSE) -> USA | G50: =VLOOKUP(C50,layoffs_location!A:E,5,FALSE) -> North America | H50: 9 | I50: 43920 | J50: 50 | K50: 18 | L50: 9 | M50: Food | N50: Seed | O50: 15 | P50: 2020 | Q50: =VLOOKUP(C50,layoffs_location!A:F,6,FALSE) -> 40.712728 | R50: =VLOOKUP(C50,layoffs_location!A:G,7,FALSE) -> -74.006015
A51: 50 | B51: Loftsmart | C51: New York City | D51: =VLOOKUP(C51,layoffs_location!A:B,2,FALSE) -> New York | E51: =VLOOKUP(C51,layoffs_location!A:C,3,FALSE) -> New York | F51: =VLOOKUP(C51,layoffs_location!A:D,4,FALSE) -> USA | G51: =VLOOKUP(C51,layoffs_location!A:E,5,FALSE) -> North America | H51: 25 | I51: 43920 | J51: 75 | K51: 33 | L51: 8 | M51: Real Estate | N51: Series A | O51: 18 | P51: 2020 | Q51: =VLOOKUP(C51,layoffs_location!A:F,6,FALSE) -> 40.712728 | R51: =VLOOKUP(C51,layoffs_location!A:G,7,FALSE) -> -74.006015
A52: 51 | B52: Maven | C52: Seattle | D52: =VLOOKUP(C52,layoffs_location!A:B,2,FALSE) -> Cascadia | E52: =VLOOKUP(C52,layoffs_location!A:C,3,FALSE) -> Washington | F52: =VLOOKUP(C52,layoffs_location!A:D,4,FALSE) -> USA | G52: =VLOOKUP(C52,layoffs_location!A:E,5,FALSE) -> North America | H52: 31 | I52: 43920 | J52: 9 | K52: 344 | L52: 313 | M52: Media | N52: Post-IPO | O52: 77 | P52: 2020 | Q52: =VLOOKUP(C52,layoffs_location!A:F,6,FALSE) -> 47.603832 | R52: =VLOOKUP(C52,layoffs_location!A:G,7,FALSE) -> -122.33006
A53: 52 | B53: PeerStreet | C53: Los Angeles | D53: =VLOOKUP(C53,layoffs_location!A:B,2,FALSE) -> other | E53: =VLOOKUP(C53,layoffs_location!A:C,3,FALSE) -> California | F53: =VLOOKUP(C53,layoffs_location!A:D,4,FALSE) -> USA | G53: =VLOOKUP(C53,layoffs_location!A:E,5,FALSE) -> North America | H53: 51 | I53: 43920 | J53: 30 | K53: 170 | L53: 119 | M53: Finance | N53: Series C | O53: 110 | P53: 2020 | Q53: =VLOOKUP(C53,layoffs_location!A:F,6,FALSE) -> 34.053691 | R53: =VLOOKUP(C53,layoffs_location!A:G,7,FALSE) -> -118.24277
...

Sheet layoffs_location
A1: location_HQ | B1: Region | C1: State | D1: Country | E1: Continent | F1: latitude | G1: longitude
A2: Adelaide | B2: other | C2: South Australia | D2: Australia | E2: Oceana | F2: -34.928181 | G2: 138.59993
A3: Agoura Hills | B3: other | C3: California | D3: USA | E3: North America | F3: 34.14791 | G3: -118.7657
A4: Ahmedabad | B4: other | C4: Gujarat | D4: India | E4: Asia | F4: 23.021624 | G4: 72.579707
A5: Alameda | B5: San Francisco Bay Area | C5: California | D5: USA | E5: North America | F5: 37.609029 | G5: -121.89914
A6: Amsterdam | B6: other | C6: non | D6: Netherlands | E6: Europe | F6: 52.37308 | G6: 4.8924534
A7: Ann Arbor | B7: other | C7: Michigan | D7: USA | E7: North America | F7: 42.281372 | G7: -83.748462
A8: Arlington | B8: other | C8: Texas | D8: USA | E8: North America | F8: 32.729131 | G8: -97.110122
A9: Atlanta | B9: other | C9: Georgia | D9: USA | E9: North America | F9: 33.748992 | G9: -84.390264
A10: Auckland | B10: other | C10: non | D10: New Zealand | E10: Oceana | F10: -36.852095 | G10: 174.76318
A11: Austin | B11: other | C11: Texas | D11: USA | E11: North America | F11: 30.271129 | G11: -97.7437
A12: Baltimore | B12: other | C12: Maryland | D12: USA | E12: North America | F12: 39.290882 | G12: -76.610759
A13: Bangkok | B13: other | C13: non | D13: Thailand | E13: Asia | F13: 13.752494 | G13: 100.49351
... A248: Walldorf | B248: other | C248: Baden-Würtemberg | D248: Germany | E248: Europe | F248: 49.303813 | G248: 8.6433518
A249: Walnut | B249: San Francisco Bay Area | C249: California | D249: USA | E249: North America | F249: 37,910076 | G249: -122.06519
A250: Walnut Creek | B250: San Francisco Bay Area | C250: California | D250: USA | E250: North America | F250: 37.910076 | G250: -122.06519
A251: Waltham | B251: other | C251: Massachusetts | D251: USA | E251: North America | F251: 42.37564 | G251: -71.2358
A252: Warsaw | B252: other | C252: non | D252: Poland | E252: Europe | F252: 52.233717 | G252: 21.071432
A253: Washington DC | B253: other | C253: District of Columbia | D253: USA | E253: North America | F253: 38.895037 | G253: -77.036543
A254: Waterloo | B254: other | C254: Ontario | D254: Canada | E254: North America | F254: 43.46527 | G254: -80.522296
A255: Wellington | B255: other | C255: non | D255: New Zealand | E255: Oceana | F255: -41.288795 | G255: 174.77721
A256: Wilmington | B256: other | C256: Delaware | D256: USA | E256: North America | F256: 39.745947 | G256: -75.546589
A257: Winnipeg | B257: other | C257: Manitoba | D257: Canada | E257: North America | F257: 49.895077 | G257: -97.138451
A258: Xi'an | B258: other | C258: non | D258: China | E258: Asia | F258: 34.261004 | G258: 108.94234
A259: Yavne | B259: other | C259: non | D259: Israel | E259: Asia | F259: 31.876886 | G259: 34.738297
A260: Zephyr Cove | B260: other | C260: Nevada | D260: USA | E260: North America | F260: 39.002873 | G260: -119.93738
A261: Zurich | B261: other | C261: non | D261: Switzerland | E261: Europe | F261: 47.374449 | G261: 8.5410422

Sheet companies
A1: company-name | B1: company-code | C1: Emplyees_202601 | D1: Country
A2: Amazon | B2: AMZN | C2: 1546000 | D2: USA
A3: Jingdong Mall | B3: JD | C3: 900000 | D3: China
A4: Foxconn | B4: 2317.TW | C4: 826608 | D4: Taiwan
A5: IBM | B5: IBM | C5: 270300 | D5: USA
A6: Microsoft | B6: MSFT | C6: 228000 | D6: USA
A7: Panasonic | B7: 6752.T | C7: 207548 | D7: Japan
A8: Google | B8: GOOG | C8: 187103 | D8: USA
A9: Oracle | B9: ORCL | C9: 162000 | D9: USA
A10: Schneider Electric | B10: SU.PA | C10: 155822 | D10: France
A11: Apple | B11: AAPL | C11: 150000 | D11: USA
A12: Genpact | B12: G | C12: 146000 | D12: Bermuda
A13: Tesla | B13: TSLA | C13: 125665 | D13: USA
... A565: D2L Inc. | B565: DTOL.TO | C565: 1000 | D565: Canada
A566: Upland Software | B566: UPLD | C566: 998 | D566: USA
A567: SAKURA Internet | B567: 3778.T | C567: 997 | D567: Japan
A568: WithSecure Oyj | B568: WITH.HE | C568: 993 | D568: Finland
A569: Appen | B569: APX.AX | C569: 992 | D569: Australia
A570: Docebo | B570: DCBO | C570: 991 | D570: Canada
A571: Trainline | B571: TRN.L | C571: 990 | D571: UK
A572: Trustpilot Group | B572: TRST.L | C572: 988 | D572: Denmark
A573: Quick Heal | B573: QUICKHEAL.NS | C573: 986 | D573: India
A574: Zip Co | B574: ZIP.AX | C574: 985 | D574: Australia
A575: Cambricon Technologies | B575: 688256.SS | C575: 980 | D575: China
A576: PEXA Group | B576: PXA.AX | C576: 968 | D576: Australia
A577: LegalZoom | B577: LZ | C577: 964 | D577: USA
... A1004: Sphere 3D | B1004: ANY | C1004: 2 | D1004: Canada
A1005: Sonatype | B1005: =VLOOKUP(A1005,[1]StockPrice!$C:$D,2,FALSE) -> #N/A
A1006: Redbubble | B1006: =VLOOKUP(A1006,[1]StockPrice!$C:$D,2,FALSE) -> #N/A
A1007: Cornershop | B1007: =VLOOKUP(A1007,[1]StockPrice!$C:$D,2,FALSE) -> #N/A
A1008: Happay | B1008: =VLOOKUP(A1008,[1]StockPrice!$C:$D,2,FALSE) -> #N/A
A1009: Lemonade | B1009: =VLOOKUP(A1009,[1]StockPrice!$C:$D,2,FALSE) -> 39.8946
A1010: Zepz | B1010: =VLOOKUP(A1010,[1]StockPrice!$C:$D,2,FALSE) -> #N/A
A1011: Pie Insurance | B1011: =VLOOKUP(A1011,[1]StockPrice!$C:$D,2,FALSE) -> #N/A
A1012: Guild | B1012: =VLOOKUP(A1012,[1]StockPrice!$C:$D,2,FALSE) -> #N/A
A1013: Western Digital | B1013: =VLOOKUP(A1013,[1]StockPrice!$C:$D,2,FALSE) -> 10.8611
A1014: Airmeet | B1014: =VLOOKUP(A1014,[1]StockPrice!$C:$D,2,FALSE) -> #N/A
A1015: Evolve | B1015: =VLOOKUP(A1015,[1]StockPrice!$C:$D,2,FALSE) -> #N/A
A1016: Taxfix | B1016: =VLOOKUP(A1016,[1]StockPrice!$C:$D,2,FALSE) -> #N/A
... A1400: Priceline | B1400: =VLOOKUP(A1400,[1]StockPrice!$C:$D,2,FALSE) -> #N/A
...
